Workbook

Sheet ANALİZ
AY1: Sorting numbers from largest to smallest
AO2: Parameters
G3: HORSE RACES RESULT | L3: JOKEY RACES RESULT | Q3: FATHER RACES RESULT | V3: MOTHER RAC ES RESULT | AA3: MOTHER'S FATHER RACES RESULT | AF3: 0.3 | AG3: 0.15 | AO3: 45 | AP3: 35 | AQ3: 8 | AR3: 6 | AS3: 2 | AT3: 5 | AU3: 5 | AV3: 10
B4: RACING BREED | C4: WEIGHT | D4: EARNING | E4: AVERAGE PER RACE | F4: RACE QUANTITY | G4: TOPLAM | H4: 1. | I4: 2. | J4: 3. | K4: 4. | L4: TOPLAM | M4: 1. | N4: 2. | O4: 3. | P4: 4. | Q4: TOPLAM | R4: 1. | S4: 2. | T4: 3. | U4: 4. | V4: TOPLAM | W4: 1. | X4: 2. | Y4: 3. | Z4: 4. | AA4: TOPLAM | AB4: 1. | AC4: 2. | AD4: 3. | AE4: 4. | AF4: HORSE POWER | AG4: JOCKHEY POWER | AH4: FATHET POWER | AI4: MOTHER POWER | AJ4: MOTHER'S FATHER POWER | AK4: PERDİGEE POWER | AL4: EARNING POWER | AM4: WEIGHT EFFECT | AO4: Horse | AP4: Jockey | AQ4: Father | AR4: Mother | AS4: Mother's Father | AT4: Perdigee | AU4: Earning | AV4: Weight | AW4: RAW SCORE
B5: HAND 16 | C5: 1
A6: 1 | B6: HEKİMOĞLU KG DB SK | C6: 60 | D6: 212600 | E6: =D6/F6 -> 23622.222 | F6: =G6 -> 9 | G6: 9 | H6: 0 | I6: 1 | J6: 1 | K6: 2 | L6: 112 | M6: 9 | N6: 11 | O6: 12 | P6: 9 | Q6: 14861 | R6: 2182 | S6: 1832 | T6: 1508 | U6: 1403 | V6: 182 | W6: 17 | X6: 17 | Y6: 21 | Z6: 18 | AA6: 1838 | AB6: 170 | AC6: 167 | AD6: 183 | AE6: 168 | AF6: =(H6/G6*4)+(I6/G6*3)+(J6/G6*2)+(K6/G6*1) -> 0.77777778 | AG6: =(M6/L6*4)+(N6/L6*3)+(O6/L6*2)+(P6/L6*1) -> 0.91071429 | AH6: =(R6/Q6*4)+(S6/Q6*3)+(T6/Q6*2)+(U6/Q6*1) -> 1.2544916 | AI6: =(W6/V6*4)+(X6/V6*3)+(Y6/V6*2)+(Z6/V6*1) -> 0.98351648 | AJ6: =(AB6/AA6*4)+(AC6/AA6*3)+(AD6/AA6*2)+(AE6/AA6*1) -> 0.93307943 | AK6: =AVERAGE(AH6:AJ6) -> 1.0570292 | AL6: =E6/MAX($E$6:$E$15) -> 0.25085546 | AM6: =(AVERAGE($C$6:$C$15)-C6)/AVERAGE($C$6:$C$15) -> -0.034482759 | AO6: =AF6*$AO$3 -> 35 | AP6: =AG6*$AP$3 -> 31.875 | AQ6: =AH6*$AQ$3 -> 10.035933 | AR6: =AI6*$AR$3 -> 5.9010989 | AS6: =AJ6*$AS$3 -> 1.8661589 | AT6: =AK6*$AT$3 -> 5.2851459 | AU6: =AL6*$AU$3 -> 1.2542773 | AV6: =AM6*$AV$3 -> -0.34482759 | AW6: =(AO6)+(AP6)+(AT6)+(AU6)+(AV6) -> 73.069596 | AY6: 4 | AZ6: 169.31356
A7: 2 | B7: DELİ YILDIRIM KG DB SK | C7: 59.5 | D7: 236350 | E7: =D7/F7 -> 26261.111 | F7: =G7 -> 9 | G7: 9 | H7: 0 | I7: 1 | J7: 1 | K7: 3 | L7: 30 | M7: 2 | N7: 5 | O7: 3 | P7: 0 | Q7: 14023 | R7: 1794 | S7: 1680 | T7: 1463 | U7: 1419 | V7: 189 | W7: 19 | X7: 24 | Y7: 27 | Z7: 17 | AA7: 1802 | AB7: 164 | AC7: 169 | AD7: 176 | AE7: 154 | AF7: =(H7/G7*4)+(I7/G7*3)+(J7/G7*2)+(K7/G7*1) -> 0.88888889 | AG7: =(M7/L7*4)+(N7/L7*3)+(O7/L7*2)+(P7/L7*1) -> 0.96666667 | AH7: =(R7/Q7*4)+(S7/Q7*3)+(T7/Q7*2)+(U7/Q7*1) -> 1.1809884 | AI7: =(W7/V7*4)+(X7/V7*3)+(Y7/V7*2)+(Z7/V7*1) -> 1.1587302 | AJ7: =(AB7/AA7*4)+(AC7/AA7*3)+(AD7/AA7*2)+(AE7/AA7*1) -> 0.92619312 | AL7: =E7/MAX($E$6:$E$15) -> 0.27887906 | AM7: =(AVERAGE($C$6:$C$15)-C7)/AVERAGE($C$6:$C$15)*2 -> -0.051724138 | AO7: =AF7*$AO$3 -> 40 | AP7: =AG7*$AP$3 -> 33.833333 | AQ7: =AH7*$AQ$3 -> 9.447907 | AR7: =AI7*$AR$3 -> 6.952381 | AS7: =AJ7*$AS$3 -> 1.8523862 | AT7: =AK7*$AT$3 -> 0 | AU7: =AL7*$AU$3 -> 1.3943953 | AV7: =AM7*$AV$3 -> -0.51724138 | AW7: =(AO7)+(AP7)+(AT7)+(AU7)+(AV7) -> 74.710487 | AY7: 3 | AZ7: 159.52978
A8: 3 | B8: CANYURT KG DB SK | C8: 62 | D8: 847500 | E8: =D8/F8 -> 94166.667 | F8: =G8 -> 9 | G8: 9 | H8: 3 | I8: 1 | J8: 3 | K8: 0 | L8: 77 | M8: 12 | N8: 14 | O8: 8 | P8: 6 | Q8: 8478 | R8: 1085 | S8: 1011 | T8: 971 | U8: 943 | V8: 67 | W8: 7 | X8: 7 | Y8: 9 | Z8: 4 | AA8: 2756 | AB8: 334 | AC8: 290 | AD8: 317 | AE8: 297 | AF8: =(H8/G8*4)+(I8/G8*3)+(J8/G8*2)+(K8/G8*1) -> 2.3333333 | AG8: =(M8/L8*4)+(N8/L8*3)+(O8/L8*2)+(P8/L8*1) -> 1.4545455 | AH8: =(R8/Q8*4)+(S8/Q8*3)+(T8/Q8*2)+(U8/Q8*1) -> 1.2099552 | AI8: =(W8/V8*4)+(X8/V8*3)+(Y8/V8*2)+(Z8/V8*1) -> 1.0597015 | AJ8: =(AB8/AA8*4)+(AC8/AA8*3)+(AD8/AA8*2)+(AE8/AA8*1) -> 1.1382438 | AL8: =E8/MAX($E$6:$E$15) -> 1 | AM8: =(AVERAGE($C$6:$C$15)-C8)/AVERAGE($C$6:$C$15)*2 -> -0.13793103 | AO8: =AF8*$AO$3 -> 105 | AP8: =AG8*$AP$3 -> 50.909091 | AQ8: =AH8*$AQ$3 -> 9.6796414 | AR8: =AI8*$AR$3 -> 6.358209 | AS8: =AJ8*$AS$3 -> 2.2764877 | AT8: =AK8*$AT$3 -> 0 | AU8: =AL8*$AU$3 -> 5 | AV8: =AM8*$AV$3 -> -1.3793103 | AW8: =(AO8)+(AP8)+(AT8)+(AU8)+(AV8) -> 159.52978 | AY8: 8 | AZ8: 119.57459
A9: 4 | B9: HIZLI AYAK KG SK | C9: 59.5 | D9: 887300 | E9: =D9/F9 -> 88730 | F9: =G9 -> 10 | G9: 10 | H9: 3 | I9: 3 | J9: 0 | K9: 0 | L9: 339 | M9: 89 | N9: 60 | O9: 52 | P9: 44 | Q9: 1069 | R9: 121 | S9: 133 | T9: 126 | U9: 93 | V9: 199 | W9: 29 | X9: 24 | Y9: 21 | Z9: 19 | AA9: 5789 | AB9: 604 | AC9: 553 | AD9: 556 | AE9: 571 | AF9: =(H9/G9*4)+(I9/G9*3)+(J9/G9*2)+(K9/G9*1) -> 2.1 | AG9: =(M9/L9*4)+(N9/L9*3)+(O9/L9*2)+(P9/L9*1) -> 2.0176991 | AH9: =(R9/Q9*4)+(S9/Q9*3)+(T9/Q9*2)+(U9/Q9*1) -> 1.1487371 | AI9: =(W9/V9*4)+(X9/V9*3)+(Y9/V9*2)+(Z9/V9*1) -> 1.2512563 | AJ9: =(AB9/AA9*4)+(AC9/AA9*3)+(AD9/AA9*2)+(AE9/AA9*1) -> 0.99464502 | AL9: =E9/MAX($E$6:$E$15) -> 0.94226549 | AM9: =(AVERAGE($C$6:$C$15)-C9)/AVERAGE($C$6:$C$15)*2 -> -0.051724138 | AO9: =AF9*$AO$3 -> 94.5 | AP9: =AG9*$AP$3 -> 70.619469 | AQ9: =AH9*$AQ$3 -> 9.1898971 | AR9: =AI9*$AR$3 -> 7.5075377 | AS9: =AJ9*$AS$3 -> 1.98929 | AT9: =AK9*$AT$3 -> 0 | AU9: =AL9*$AU$3 -> 4.7113274 | AV9: =AM9*$AV$3 -> -0.51724138 | AW9: =(AO9)+(AP9)+(AT9)+(AU9)+(AV9) -> 169.31356 | AY9: 10 | AZ9: 113.20019
A10: 5 | B10: SADEKAR KG DB SK | C10: 59 | D10: 418000 | E10: =D10/F10 -> 46444.444 | F10: =G10 -> 9 | G10: 9 | H10: 1 | I10: 1 | J10: 0 | K10: 3 | L10: 52 | M10: 3 | N10: 4 | O10: 4 | P10: 6 | Q10: 14861 | R10: 2182 | S10: 1832 | T10: 1508 | U10: 1403 | V10: 103 | W10: 6 | X10: 9 | Y10: 11 | Z10: 13 | AA10: 3342 | AB10: 332 | AC10: 348 | AD10: 341 | AE10: 330 | AF10: =(H10/G10*4)+(I10/G10*3)+(J10/G10*2)+(K10/G10*1) -> 1.1111111 | AG10: =(M10/L10*4)+(N10/L10*3)+(O10/L10*2)+(P10/L10*1) -> 0.73076923 | AH10: =(R10/Q10*4)+(S10/Q10*3)+(T10/Q10*2)+(U10/Q10*1) -> 1.2544916 | AI10: =(W10/V10*4)+(X10/V10*3)+(Y10/V10*2)+(Z10/V10*1) -> 0.83495146 | AJ10: =(AB10/AA10*4)+(AC10/AA10*3)+(AD10/AA10*2)+(AE10/AA10*1) -> 1.0125673 | AK10: =AVERAGE(AH10:AJ10) -> 1.0340035 | AL10: =E10/MAX($E$6:$E$15) -> 0.49321534 | AM10: =(AVERAGE($C$6:$C$15)-C10)/AVERAGE($C$6:$C$15)*2 -> -0.034482759 | AO10: =AF10*$AO$3 -> 50 | AP10: =AG10*$AP$3 -> 25.576923 | AQ10: =AH10*$AQ$3 -> 10.035933 | AR10: =AI10*$AR$3 -> 5.0097087 | AS10: =AJ10*$AS$3 -> 2.0251346 | AT10: =AK10*$AT$3 -> 5.1700173 | AU10: =AL10*$AU$3 -> 2.4660767 | AV10: =AM10*$AV$3 -> -0.34482759 | AW10: =(AO10)+(AP10)+(AT10)+(AU10)+(AV10) -> 82.86819 | AY10: 5 | AZ10: 82.86819
A11: 6 | B11: ALEVKIRAN KG DB SK GKR | C11: 60.5 | D11: 280000 | E11: =D11/F11 -> 31111.111 | F11: =G11 -> 9 | G11: 9 | H11: 1 | I11: 0 | J11: 0 | K11: 0 | L11: 81 | M11: 8 | N11: 5 | O11: 7 | P11: 13 | Q11: 2125 | R11: 247 | S11: 269 | T11: 243 | U11: 209 | V11: 166 | W11: 9 | X11: 17 | Y11: 21 | Z11: 8 | AA11: 3485 | AB11: 304 | AC11: 301 | AD11: 327 | AE11: 285 | AF11: =(H11/G11*4)+(I11/G11*3)+(J11/G11*2)+(K11/G11*1) -> 0.44444444 | AG11: =(M11/L11*4)+(N11/L11*3)+(O11/L11*2)+(P11/L11*1) -> 0.91358025 | AH11: =(R11/Q11*4)+(S11/Q11*3)+(T11/Q11*2)+(U11/Q11*1) -> 1.1717647 | AI11: =(W11/V11*4)+(X11/V11*3)+(Y11/V11*2)+(Z11/V11*1) -> 0.8253012 | AJ11: =(AB11/AA11*4)+(AC11/AA11*3)+(AD11/AA11*2)+(AE11/AA11*1) -> 0.87747489 | AK11: =AVERAGE(AH11:AJ11) -> 0.95818027 | AL11: =E11/MAX($E$6:$E$15) -> 0.33038348 | AM11: =(AVERAGE($C$6:$C$15)-C11)/AVERAGE($C$6:$C$15)*2 -> -0.086206897 | AO11: =AF11*$AO$3 -> 20 | AP11: =AG11*$AP$3 -> 31.975309 | AQ11: =AH11*$AQ$3 -> 9.3741176 | AR11: =AI11*$AR$3 -> 4.9518072 | AS11: =AJ11*$AS$3 -> 1.7549498 | AT11: =AK11*$AT$3 -> 4.7909013 | AU11: =AL11*$AU$3 -> 1.6519174 | AV11: =AM11*$AV$3 -> -0.86206897 | AW11: =(AO11)+(AP11)+(AT11)+(AU11)+(AV11) -> 57.556058 | AY11: 7 | AZ11: 81.139711
A12: 7 | B12: TURBODİZEL KG | C12: 58 | D12: 170400 | E12: =D12/F12 -> 17040 | F12: =G12 -> 10 | G12: 10 | H12: 0 | I12: 1 | J12: 1 | K12: 3 | L12: 259 | M12: 28 | N12: 28 | O12: 26 | P12: 37 | Q12: 14023 | R12: 1794 | S12: 1680 | T12: 1463 | U12: 1419 | V12: 44 | W12: 5 | X12: 3 | Y12: 8 | Z12: 7 | AA12: 6296 | AB12: 675 | AC12: 712 | AD12: 632 | AE12: 637 | AF12: =(H12/G12*4)+(I12/G12*3)+(J12/G12*2)+(K12/G12*1) -> 0.8 | AG12: =(M12/L12*4)+(N12/L12*3)+(O12/L12*2)+(P12/L12*1) -> 1.1003861 | AH12: =(R12/Q12*4)+(S12/Q12*3)+(T12/Q12*2)+(U12/Q12*1) -> 1.1809884 | AI12: =(W12/V12*4)+(X12/V12*3)+(Y12/V12*2)+(Z12/V12*1) -> 1.1818182 | AJ12: =(AB12/AA12*4)+(AC12/AA12*3)+(AD12/AA12*2)+(AE12/AA12*1) -> 1.0700445 | AK12: =AVERAGE(AH12:AJ12) -> 1.1442837 | AL12: =E12/MAX($E$6:$E$15) -> 0.18095575 | AM12: =(AVERAGE($C$6:$C$15)-C12)/AVERAGE($C$6:$C$15)*2 -> 0 | AO12: =AF12*$AO$3 -> 36 | AP12: =AG12*$AP$3 -> 38.513514 | AQ12: =AH12*$AQ$3 -> 9.447907 | AR12: =AI12*$AR$3 -> 7.0909091 | AS12: =AJ12*$AS$3 -> 2.1400889 | AT12: =AK12*$AT$3 -> 5.7214184 | AU12: =AL12*$AU$3 -> 0.90477876 | AV12: =AM12*$AV$3 -> 0 | AW12: =(AO12)+(AP12)+(AT12)+(AU12)+(AV12) -> 81.139711 | AY12: 9 | AZ12: 75.04045
A13: 8 | B13: ÇAĞLAYANŞELALE KG K DB | C13: 58.5 | D13: 287400 | E13: =D13/F13 -> 31933.333 | F13: =G13 -> 9 | G13: 9 | H13: 0 | I13: 3 | J13: 1 | K13: 0 | L13: 281 | M13: 53 | N13: 43 | O13: 36 | P13: 45 | Q13: 14861 | R13: 2182 | S13: 1832 | T13: 1508 | U13: 1403 | V13: 271 | W13: 44 | X13: 32 | Y13: 32 | Z13: 24 | AA13: 14359 | AB13: 1509 | AC13: 1475 | AD13: 1390 | AE13: 1408 | AF13: =(H13/G13*4)+(I13/G13*3)+(J13/G13*2)+(K13/G13*1) -> 1.2222222 | AG13: =(M13/L13*4)+(N13/L13*3)+(O13/L13*2)+(P13/L13*1) -> 1.6298932 | AH13: =(R13/Q13*4)+(S13/Q13*3)+(T13/Q13*2)+(U13/Q13*1) -> 1.2544916 | AI13: =(W13/V13*4)+(X13/V13*3)+(Y13/V13*2)+(Z13/V13*1) -> 1.3284133 | AJ13: =(AB13/AA13*4)+(AC13/AA13*3)+(AD13/AA13*2)+(AE13/AA13*1) -> 1.0201964 | AK13: =AVERAGE(AH13:AJ13) -> 1.2010338 | AL13: =E13/MAX($E$6:$E$15) -> 0.33911504 | AM13: =(AVERAGE($C$6:$C$15)-C13)/AVERAGE($C$6:$C$15)*2 -> -0.017241379 | AO13: =AF13*$AO$3 -> 55 | AP13: =AG13*$AP$3 -> 57.046263 | AQ13: =AH13*$AQ$3 -> 10.035933 | AR13: =AI13*$AR$3 -> 7.9704797 | AS13: =AJ13*$AS$3 -> 2.0403928 | AT13: =AK13*$AT$3 -> 6.0051688 | AU13: =AL13*$AU$3 -> 1.6955752 | AV13: =AM13*$AV$3 -> -0.17241379 | AW13: =(AO13)+(AP13)+(AT13)+(AU13)+(AV13) -> 119.57459 | AY13: 2 | AZ13: 74.710487
A14: 9 | B14: HOSLİ KG DB SK GKR | C14: 53 | D14: 269300 | E14: =D14/F14 -> 29922.222 | F14: =G14 -> 9 | G14: 9 | H14: 0 | I14: 2 | J14: 1 | K14: 1 | L14: 13 | M14: 0 | N14: 2 | O14: 0 | P14: 2 | Q14: 14861 | R14: 2182 | S14: 1832 | T14: 1508 | U14: 1403 | V14: 78 | W14: 7 | X14: 9 | Y14: 4 | Z14: 6 | AA14: 857 | AB14: 82 | AC14: 87 | AD14: 80 | AE14: 86 | AF14: =(H14/G14*4)+(I14/G14*3)+(J14/G14*2)+(K14/G14*1) -> 1 | AG14: =(M14/L14*4)+(N14/L14*3)+(O14/L14*2)+(P14/L14*1) -> 0.61538462 | AH14: =(R14/Q14*4)+(S14/Q14*3)+(T14/Q14*2)+(U14/Q14*1) -> 1.2544916 | AI14: =(W14/V14*4)+(X14/V14*3)+(Y14/V14*2)+(Z14/V14*1) -> 0.88461538 | AJ14: =(AB14/AA14*4)+(AC14/AA14*3)+(AD14/AA14*2)+(AE14/AA14*1) -> 0.97432905 | AK14: =AVERAGE(AH14:AJ14) -> 1.037812 | AL14: =E14/MAX($E$6:$E$15) -> 0.31775811 | AM14: =(AVERAGE($C$6:$C$15)-C14)/AVERAGE($C$6:$C$15)*2 -> 0.17241379 | AO14: =AF14*$AO$3 -> 45 | AP14: =AG14*$AP$3 -> 21.538462 | AQ14: =AH14*$AQ$3 -> 10.035933 | AR14: =AI14*$AR$3 -> 5.3076923 | AS14: =AJ14*$AS$3 -> 1.9486581 | AT14: =AK14*$AT$3 -> 5.1890601 | AU14: =AL14*$AU$3 -> 1.5887906 | AV14: =AM14*$AV$3 -> 1.7241379 | AW14: =(AO14)+(AP14)+(AT14)+(AU14)+(AV14) -> 75.04045 | AY14: 1 | AZ14: 73.069596
A15: 10 | B15: KUNYA KG K DB | C15: 50 | D15: 545500 | E15: =D15/F15 -> 54550 | F15: =G15 -> 10 | G15: 10 | H15: 1 | I15: 4 | J15: 0 | K15: 1 | L15: 107 | M15: 6 | N15: 11 | O15: 8 | P15: 7 | Q15: 719 | R15: 49 | S15: 62 | T15: 72 | U15: 77 | V15: 101 | W15: 10 | X15: 13 | Y15: 11 | Z15: 9 | AA15: 10343 | AB15: 1077 | AC15: 1012 | AD15: 967 | AE15: 1048 | AF15: =(H15/G15*4)+(I15/G15*3)+(J15/G15*2)+(K15/G15*1) -> 1.7 | AG15: =(M15/L15*4)+(N15/L15*3)+(O15/L15*2)+(P15/L15*1) -> 0.74766355 | AH15: =(R15/Q15*4)+(S15/Q15*3)+(T15/Q15*2)+(U15/Q15*1) -> 0.83866481 | AI15: =(W15/V15*4)+(X15/V15*3)+(Y15/V15*2)+(Z15/V15*1) -> 1.0891089 | AJ15: =(AB15/AA15*4)+(AC15/AA15*3)+(AD15/AA15*2)+(AE15/AA15*1) -> 0.99835638 | AK15: =AVERAGE(AH15:AJ15) -> 0.9753767 | AL15: =E15/MAX($E$6:$E$15) -> 0.57929204 | AM15: =(AVERAGE($C$6:$C$15)-C15)/AVERAGE($C$6:$C$15)*2 -> 0.27586207 | AO15: =AF15*$AO$3 -> 76.5 | AP15: =AG15*$AP$3 -> 26.168224 | AQ15: =AH15*$AQ$3 -> 6.7093185 | AR15: =AI15*$AR$3 -> 6.5346535 | AS15: =AJ15*$AS$3 -> 1.9967128 | AT15: =AK15*$AT$3 -> 4.8768835 | AU15: =AL15*$AU$3 -> 2.8964602 | AV15: =AM15*$AV$3 -> 2.7586207 | AW15: =(AO15)+(AP15)+(AT15)+(AU15)+(AV15) -> 113.20019 | AY15: 6 | AZ15: 57.556058
AO16: =AF16*$AO$3 -> 0 | AP16: =AG16*$AP$3 -> 0 | AQ16: =AH16*$AQ$3 -> 0 | AR16: =AI16*$AR$3 -> 0 | AS16: =AJ16*$AS$3 -> 0 | AT16: =AK16*$AT$3 -> 0 | AU16: =AL16*$AU$3 -> 0 | AV16: =AM16*$AV$3 -> 0 | AW16: =(AO16)+(AP16)+(AT16)+(AU16)+(AV16) -> 0
B17: HAND 17 | AO17: =AF17*$AO$3 -> 0 | AP17: =AG17*$AP$3 -> 0 | AQ17: =AH17*$AQ$3 -> 0 | AR17: =AI17*$AR$3 -> 0 | AS17: =AJ17*$AS$3 -> 0 | AT17: =AK17*$AT$3 -> 0 | AU17: =AL17*$AU$3 -> 0 | AV17: =AM17*$AV$3 -> 0 | AW17: =(AO17)+(AP17)+(AT17)+(AU17)+(AV17) -> 0
A18: 1 | B18: OKLAHOMA DB SK | C18: 61 | D18: 641350 | E18: =D18/F18 -> 64135 | F18: =G18 -> 10 | G18: 10 | H18: 1 | I18: 2 | J18: 3 | K18: 1 | L18: 127 | M18: 10 | N18: 24 | O18: 12 | P18: 13 | Q18: 2253 | R18: 195 | S18: 233 | T18: 227 | U18: 222 | V18: 106 | W18: 15 | X18: 13 | Y18: 9 | Z18: 16 | AA18: 2901 | AB18: 283 | AC18: 293 | AD18: 306 | AE18: 309 | AF18: =(H18/G18*4)+(I18/G18*3)+(J18/G18*2)+(K18/G18*1) -> 1.7 | AG18: =(M18/L18*4)+(N18/L18*3)+(O18/L18*2)+(P18/L18*1) -> 1.1732283 | AH18: =(R18/Q18*4)+(S18/Q18*3)+(T18/Q18*2)+(U18/Q18*1) -> 0.95650244 | AI18: =(W18/V18*4)+(X18/V18*3)+(Y18/V18*2)+(Z18/V18*1) -> 1.254717 | AJ18: =(AB18/AA18*4)+(AC18/AA18*3)+(AD18/AA18*2)+(AE18/AA18*1) -> 1.010686 | AK18: =AVERAGE(AH18:AJ18) -> 1.0739685 | AL18: =E18/MAX($E$18:$E$27) -> 0.83270579 | AM18: =(AVERAGE($C$18:$C$27)-C18)/AVERAGE($C$18:$C$27) -> -0.09221128 | AO18: =AF18*$AO$3 -> 76.5 | AP18: =AG18*$AP$3 -> 41.062992 | AQ18: =AH18*$AQ$3 -> 7.6520195 | AR18: =AI18*$AR$3 -> 7.5283019 | AS18: =AJ18*$AS$3 -> 2.0213719 | AT18: =AK18*$AT$3 -> 5.3698423 | AU18: =AL18*$AU$3 -> 4.163529 | AV18: =AM18*$AV$3 -> -0.9221128 | AW18: =(AO18)+(AP18)+(AT18)+(AU18)+(AV18) -> 126.17425 | AY18: 3 | AZ18: 171.67878
A19: 2 | B19: ÇAKIR YILDIZI KG SK GKR | C19: 61 | D19: 642100 | E19: =D19/F19 -> 64210 | F19: =G19 -> 10 | G19: 10 | H19: 2 | I19: 1 | J19: 1 | K19: 2 | L19: 361 | M19: 69 | N19: 65 | O19: 49 | P19: 50 | Q19: 1694 | R19: 208 | S19: 206 | T19: 206 | U19: 207 | V19: 49 | W19: 11 | X19: 9 | Y19: 7 | Z19: 5 | AA19: 1959 | AB19: 218 | AC19: 237 | AD19: 209 | AE19: 202 | AF19: =(H19/G19*4)+(I19/G19*3)+(J19/G19*2)+(K19/G19*1) -> 1.5 | AG19: =(M19/L19*4)+(N19/L19*3)+(O19/L19*2)+(P19/L19*1) -> 1.7146814 | AH19: =(R19/Q19*4)+(S19/Q19*3)+(T19/Q19*2)+(U19/Q19*1) -> 1.2213695 | AI19: =(W19/V19*4)+(X19/V19*3)+(Y19/V19*2)+(Z19/V19*1) -> 1.8367347 | AJ19: =(AB19/AA19*4)+(AC19/AA19*3)+(AD19/AA19*2)+(AE19/AA19*1) -> 1.1245533 | AK19: =AVERAGE(AH19:AJ19) -> 1.3942192 | AL19: =E19/MAX($E$18:$E$27) -> 0.83367956 | AM19: =(AVERAGE($C$18:$C$27)-C19)/AVERAGE($C$18:$C$27) -> -0.09221128 | AO19: =AF19*$AO$3 -> 67.5 | AP19: =AG19*$AP$3 -> 60.01385 | AQ19: =AH19*$AQ$3 -> 9.7709563 | AR19: =AI19*$AR$3 -> 11.020408 | AS19: =AJ19*$AS$3 -> 2.2491067 | AT19: =AK19*$AT$3 -> 6.971096 | AU19: =AL19*$AU$3 -> 4.1683978 | AV19: =AM19*$AV$3 -> -0.9221128 | AW19: =(AO19)+(AP19)+(AT19)+(AU19)+(AV19) -> 137.73123 | AY19: 8 | AZ19: 166.35458
A20: 3 | B20: ASLAN LUİGİ K | C20: 59 | D20: 591150 | E20: =D20/F20 -> 59115 | F20: =G20 -> 10 | G20: 10 | H20: 4 | I20: 0 | J20: 1 | K20: 3 | L20: 379 | M20: 94 | N20: 57 | O20: 79 | P20: 51 | Q20: 4552 | R20: 445 | S20: 478 | T20: 453 | U20: 514 | V20: 39 | W20: 7 | X20: 4 | Y20: 4 | Z20: 8 | AA20: 1 | AB20: 0 | AC20: 0 | AD20: 0 | AE20: 0 | AF20: =(H20/G20*4)+(I20/G20*3)+(J20/G20*2)+(K20/G20*1) -> 2.1 | AG20: =(M20/L20*4)+(N20/L20*3)+(O20/L20*2)+(P20/L20*1) -> 1.994723 | AH20: =(R20/Q20*4)+(S20/Q20*3)+(T20/Q20*2)+(U20/Q20*1) -> 1.0180141 | AI20: =(W20/V20*4)+(X20/V20*3)+(Y20/V20*2)+(Z20/V20*1) -> 1.4358974 | AJ20: =(AB20/AA20*4)+(AC20/AA20*3)+(AD20/AA20*2)+(AE20/AA20*1) -> 0 | AK20: =AVERAGE(AH20:AJ20) -> 0.8179705 | AL20: =E20/MAX($E$18:$E$27) -> 0.76752791 | AM20: =(AVERAGE($C$18:$C$27)-C20)/AVERAGE($C$18:$C$27) -> -0.056401074 | AO20: =AF20*$AO$3 -> 94.5 | AP20: =AG20*$AP$3 -> 69.815303 | AQ20: =AH20*$AQ$3 -> 8.1441125 | AR20: =AI20*$AR$3 -> 8.6153846 | AS20: =AJ20*$AS$3 -> 0 | AT20: =AK20*$AT$3 -> 4.0898525 | AU20: =AL20*$AU$3 -> 3.8376396 | AV20: =AM20*$AV$3 -> -0.56401074 | AW20: =(AO20)+(AP20)+(AT20)+(AU20)+(AV20) -> 171.67878 | AY20: 2 | AZ20: 137.73123
A21: 4 | B21: KUMTEPER DB SKG SK SGKR | C21: 55.5 | D21: 390000 | E21: =D21/F21 -> 39000 | F21: =G21 -> 10 | G21: 10 | H21: 1 | I21: 3 | J21: 0 | K21: 2 | L21: 391 | M21: 61 | N21: 49 | O21: 51 | P21: 61 | Q21: 1694 | R21: 208 | S21: 206 | T21: 206 | U21: 207 | V21: 27 | W21: 4 | X21: 6 | Y21: 1 | Z21: 4 | AA21: 1504 | AB21: 199 | AC21: 170 | AD21: 157 | AE21: 176 | AF21: =(H21/G21*4)+(I21/G21*3)+(J21/G21*2)+(K21/G21*1) -> 1.5 | AG21: =(M21/L21*4)+(N21/L21*3)+(O21/L21*2)+(P21/L21*1) -> 1.4168798 | AH21: =(R21/Q21*4)+(S21/Q21*3)+(T21/Q21*2)+(U21/Q21*1) -> 1.2213695 | AI21: =(W21/V21*4)+(X21/V21*3)+(Y21/V21*2)+(Z21/V21*1) -> 1.4814815 | AJ21: =(AB21/AA21*4)+(AC21/AA21*3)+(AD21/AA21*2)+(AE21/AA21*1) -> 1.1941489 | AK21: =AVERAGE(AH21:AJ21) -> 1.299 | AL21: =E21/MAX($E$18:$E$27) -> 0.50636198 | AM21: =(AVERAGE($C$18:$C$27)-C21)/AVERAGE($C$18:$C$27) -> 0.006266786 | AO21: =AF21*$AO$3 -> 67.5 | AP21: =AG21*$AP$3 -> 49.590793 | AQ21: =AH21*$AQ$3 -> 9.7709563 | AR21: =AI21*$AR$3 -> 8.8888889 | AS21: =AJ21*$AS$3 -> 2.3882979 | AT21: =AK21*$AT$3 -> 6.4949999 | AU21: =AL21*$AU$3 -> 2.5318099 | AV21: =AM21*$AV$3 -> 0.06266786 | AW21: =(AO21)+(AP21)+(AT21)+(AU21)+(AV21) -> 126.18027 | AY21: 5 | AZ21: 133.94873
A22: 5 | B22: SWEPS KG DB SK | C22: 57 | D22: 475250 | E22: =D22/F22 -> 52805.556 | F22: =G22 -> 9 | G22: 9 | H22: 1 | I22: 2 | J22: 1 | K22: 2 | L22: 387 | M22: 61 | N22: 67 | O22: 57 | P22: 59 | Q22: 3320 | R22: 493 | S22: 419 | T22: 404 | U22: 375 | V22: 77 | W22: 7 | X22: 6 | Y22: 8 | Z22: 11 | AA22: 94 | AB22: 8 | AC22: 6 | AD22: 8 | AE22: 12 | AF22: =(H22/G22*4)+(I22/G22*3)+(J22/G22*2)+(K22/G22*1) -> 1.5555556 | AG22: =(M22/L22*4)+(N22/L22*3)+(O22/L22*2)+(P22/L22*1) -> 1.5968992 | AH22: =(R22/Q22*4)+(S22/Q22*3)+(T22/Q22*2)+(U22/Q22*1) -> 1.3289157 | AI22: =(W22/V22*4)+(X22/V22*3)+(Y22/V22*2)+(Z22/V22*1) -> 0.94805195 | AJ22: =(AB22/AA22*4)+(AC22/AA22*3)+(AD22/AA22*2)+(AE22/AA22*1) -> 0.82978723 | AK22: =AVERAGE(AH22:AJ22) -> 1.0355849 | AL22: =E22/MAX($E$18:$E$27) -> 0.68560836 | AM22: =(AVERAGE($C$18:$C$27)-C22)/AVERAGE($C$18:$C$27) -> -0.020590868 | AO22: =AF22*$AO$3 -> 70 | AP22: =AG22*$AP$3 -> 55.891473 | AQ22: =AH22*$AQ$3 -> 10.631325 | AR22: =AI22*$AR$3 -> 5.6883117 | AS22: =AJ22*$AS$3 -> 1.6595745 | AT22: =AK22*$AT$3 -> 5.1779247 | AU22: =AL22*$AU$3 -> 3.4280418 | AV22: =AM22*$AV$3 -> -0.20590868 | AW22: =(AO22)+(AP22)+(AT22)+(AU22)+(AV22) -> 134.29153 | AY22: 9 | AZ22: 131.4517
A23: 6 | B23: FOUDROYANT K DB | C23: 55 | D23: 770200 | E23: =D23/F23 -> 77020 | F23: =G23 -> 10 | G23: 10 | H23: 2 | I23: 3 | J23: 1 | K23: 0 | L23: 50 | M23: 1 | N23: 2 | O23: 6 | P23: 7 | Q23: 725 | R23: 61 | S23: 87 | T23: 62 | U23: 91 | V23: 25 | W23: 4 | X23: 8 | Y23: 1 | Z23: 1 | AA23: 499 | AB23: 65 | AC23: 70 | AD23: 70 | AE23: 52 | AF23: =(H23/G23*4)+(I23/G23*3)+(J23/G23*2)+(K23/G23*1) -> 1.9 | AG23: =(M23/L23*4)+(N23/L23*3)+(O23/L23*2)+(P23/L23*1) -> 0.58 | AH23: =(R23/Q23*4)+(S23/Q23*3)+(T23/Q23*2)+(U23/Q23*1) -> 0.99310345 | AI23: =(W23/V23*4)+(X23/V23*3)+(Y23/V23*2)+(Z23/V23*1) -> 1.72 | AJ23: =(AB23/AA23*4)+(AC23/AA23*3)+(AD23/AA23*2)+(AE23/AA23*1) -> 1.3266533 | AK23: =AVERAGE(AH23:AJ23) -> 1.3465856 | AL23: =E23/MAX($E$18:$E$27) -> 1 | AM23: =(AVERAGE($C$18:$C$27)-C23)/AVERAGE($C$18:$C$27) -> 0.015219338 | AO23: =AF23*$AO$3 -> 85.5 | AP23: =AG23*$AP$3 -> 20.3 | AQ23: =AH23*$AQ$3 -> 7.9448276 | AR23: =AI23*$AR$3 -> 10.32 | AS23: =AJ23*$AS$3 -> 2.6533066 | AT23: =AK23*$AT$3 -> 6.7329279 | AU23: =AL23*$AU$3 -> 5 | AV23: =AM23*$AV$3 -> 0.15219338 | AW23: =(AO23)+(AP23)+(AT23)+(AU23)+(AV23) -> 117.68512 | AY23: 4 | AZ23: 126.18027
A24: 7 | B24: MR BIG SHOT DB BB | C24: 53.5 | D24: 181925 | E24: =D24/F24 -> 18192.5 | F24: =G24 -> 10 | G24: 10 | H24: 0 | I24: 1 | J24: 3 | K24: 0 | L24: 281 | M24: 53 | N24: 43 | O24: 36 | P24: 45 | Q24: 3320 | R24: 493 | S24: 419 | T24: 404 | U24: 375 | V24: 142 | W24: 9 | X24: 21 | Y24: 19 | Z24: 17 | AA24: 512 | AB24: 49 | AC24: 68 | AD24: 63 | AE24: 63 | AF24: =(H24/G24*4)+(I24/G24*3)+(J24/G24*2)+(K24/G24*1) -> 0.9 | AG24: =(M24/L24*4)+(N24/L24*3)+(O24/L24*2)+(P24/L24*1) -> 1.6298932 | AH24: =(R24/Q24*4)+(S24/Q24*3)+(T24/Q24*2)+(U24/Q24*1) -> 1.3289157 | AI24: =(W24/V24*4)+(X24/V24*3)+(Y24/V24*2)+(Z24/V24*1) -> 1.084507 | AJ24: =(AB24/AA24*4)+(AC24/AA24*3)+(AD24/AA24*2)+(AE24/AA24*1) -> 1.1503906 | AK24: =AVERAGE(AH24:AJ24) -> 1.1879378 | AL24: =E24/MAX($E$18:$E$27) -> 0.23620488 | AM24: =(AVERAGE($C$18:$C$27)-C24)/AVERAGE($C$18:$C$27) -> 0.042076992 | AO24: =AF24*$AO$3 -> 40.5 | AP24: =AG24*$AP$3 -> 57.046263 | AQ24: =AH24*$AQ$3 -> 10.631325 | AR24: =AI24*$AR$3 -> 6.5070423 | AS24: =AJ24*$AS$3 -> 2.3007812 | AT24: =AK24*$AT$3 -> 5.9396889 | AU24: =AL24*$AU$3 -> 1.1810244 | AV24: =AM24*$AV$3 -> 0.42076992 | AW24: =(AO24)+(AP24)+(AT24)+(AU24)+(AV24) -> 105.08775 | AY24: 1 | AZ24: 126.17425
A25: 8 | B25: SİLİSTRE KG K | C25: 55 | D25: 526225 | E25: =D25/F25 -> 52622.5 | F25: =G25 -> 10 | G25: 10 | H25: 3 | I25: 3 | J25: 2 | K25: 0 | L25: 89 | M25: 12 | N25: 13 | O25: 8 | P25: 8 | Q25: 3320 | R25: 493 | S25: 419 | T25: 404 | U25: 375 | V25: 18 | W25: 4 | X25: 3 | Y25: 2 | Z25: 0 | AA25: 516 | AB25: 43 | AC25: 59 | AD25: 68 | AE25: 52 | AF25: =(H25/G25*4)+(I25/G25*3)+(J25/G25*2)+(K25/G25*1) -> 2.5 | AG25: =(M25/L25*4)+(N25/L25*3)+(O25/L25*2)+(P25/L25*1) -> 1.247191 | AH25: =(R25/Q25*4)+(S25/Q25*3)+(T25/Q25*2)+(U25/Q25*1) -> 1.3289157 | AI25: =(W25/V25*4)+(X25/V25*3)+(Y25/V25*2)+(Z25/V25*1) -> 1.6111111 | AJ25: =(AB25/AA25*4)+(AC25/AA25*3)+(AD25/AA25*2)+(AE25/AA25*1) -> 1.0406977 | AK25: =AVERAGE(AH25:AJ25) -> 1.3269081 | AL25: =E25/MAX($E$18:$E$27) -> 0.68323163 | AM25: =(AVERAGE($C$18:$C$27)-C25)/AVERAGE($C$18:$C$27) -> 0.015219338 | AO25: =AF25*$AO$3 -> 112.5 | AP25: =AG25*$AP$3 -> 43.651685 | AQ25: =AH25*$AQ$3 -> 10.631325 | AR25: =AI25*$AR$3 -> 9.6666667 | AS25: =AJ25*$AS$3 -> 2.0813953 | AT25: =AK25*$AT$3 -> 6.6345407 | AU25: =AL25*$AU$3 -> 3.4161581 | AV25: =AM25*$AV$3 -> 0.15219338 | AW25: =(AO25)+(AP25)+(AT25)+(AU25)+(AV25) -> 166.35458 | AY25: 6 | AZ25: 117.68512
A26: 9 | B26: CATCH THE STARS SK | C26: 51.5 | D26: 606800 | E26: =D26/F26 -> 60680 | F26: =G26 -> 10 | G26: 10 | H26: 2 | I26: 2 | J26: 1 | K26: 1 | L26: 428 | M26: 65 | N26: 49 | O26: 48 | P26: 57 | Q26: 12123 | R26: 1511 | S26: 1395 | T26: 1444 | U26: 1277 | V26: 63 | W26: 9 | X26: 11 | Y26: 11 | Z26: 2 | AA26: 1 | AB26: 0 | AC26: 0 | AD26: 0 | AE26: 0 | AF26: =(H26/G26*4)+(I26/G26*3)+(J26/G26*2)+(K26/G26*1) -> 1.7 | AG26: =(M26/L26*4)+(N26/L26*3)+(O26/L26*2)+(P26/L26*1) -> 1.3084112 | AH26: =(R26/Q26*4)+(S26/Q26*3)+(T26/Q26*2)+(U26/Q26*1) -> 1.1873299 | AI26: =(W26/V26*4)+(X26/V26*3)+(Y26/V26*2)+(Z26/V26*1) -> 1.4761905 | AJ26: =(AB26/AA26*4)+(AC26/AA26*3)+(AD26/AA26*2)+(AE26/AA26*1) -> 0 | AK26: =AVERAGE(AH26:AJ26) -> 0.88784012 | AL26: =E26/MAX($E$18:$E$27) -> 0.78784731 | AM26: =(AVERAGE($C$18:$C$27)-C26)/AVERAGE($C$18:$C$27) -> 0.077887198 | AO26: =AF26*$AO$3 -> 76.5 | AP26: =AG26*$AP$3 -> 45.794393 | AQ26: =AH26*$AQ$3 -> 9.498639 | AR26: =AI26*$AR$3 -> 8.8571429 | AS26: =AJ26*$AS$3 -> 0 | AT26: =AK26*$AT$3 -> 4.4392006 | AU26: =AL26*$AU$3 -> 3.9392366 | AV26: =AM26*$AV$3 -> 0.77887198 | AW26: =(AO26)+(AP26)+(AT26)+(AU26)+(AV26) -> 131.4517 | AY26: 10 | AZ26: 106.90864
A27: 10 | B27: KING OF THE WIN KG DB SK | C27: 50 | D27: 381400 | E27: =D27/F27 -> 38140 | F27: =G27 -> 10 | G27: 10 | H27: 3 | I27: 0 | J27: 2 | K27: 0 | L27: 107 | M27: 6 | N27: 11 | O27: 8 | P27: 7 | Q27: 14421 | R27: 1830 | S27: 1734 | T27: 1760 | U27: 1697 | V27: 21 | W27: 3 | X27: 0 | Y27: 2 | Z27: 3 | AA27: 215 | AB27: 26 | AC27: 14 | AD27: 17 | AE27: 34 | AF27: =(H27/G27*4)+(I27/G27*3)+(J27/G27*2)+(K27/G27*1) -> 1.6 | AG27: =(M27/L27*4)+(N27/L27*3)+(O27/L27*2)+(P27/L27*1) -> 0.74766355 | AH27: =(R27/Q27*4)+(S27/Q27*3)+(T27/Q27*2)+(U27/Q27*1) -> 1.2300811 | AI27: =(W27/V27*4)+(X27/V27*3)+(Y27/V27*2)+(Z27/V27*1) -> 0.9047619 | AJ27: =(AB27/AA27*4)+(AC27/AA27*3)+(AD27/AA27*2)+(AE27/AA27*1) -> 0.99534884 | AK27: =AVERAGE(AH27:AJ27) -> 1.0433973 | AL27: =E27/MAX($E$18:$E$27) -> 0.49519605 | AM27: =(AVERAGE($C$18:$C$27)-C27)/AVERAGE($C$18:$C$27) -> 0.10474485 | AO27: =AF27*$AO$3 -> 72 | AP27: =AG27*$AP$3 -> 26.168224 | AQ27: =AH27*$AQ$3 -> 9.8406491 | AR27: =AI27*$AR$3 -> 5.4285714 | AS27: =AJ27*$AS$3 -> 1.9906977 | AT27: =AK27*$AT$3 -> 5.2169865 | AU27: =AL27*$AU$3 -> 2.4759803 | AV27: =AM27*$AV$3 -> 1.0474485 | AW27: =(AO27)+(AP27)+(AT27)+(AU27)+(AV27) -> 106.90864 | AY27: 7 | AZ27: 105.08775
AF28: =(H28/G28*4)+(I28/G28*3)+(J28/G28*2)+(K28/G28*1) -> #DIV/0! | AG28: =(M28/L28*4)+(N28/L28*3)+(O28/L28*2)+(P28/L28*1) -> #DIV/0! | AH28: =(R28/Q28*4)+(S28/Q28*3)+(T28/Q28*2)+(U28/Q28*1) -> #DIV/0! | AI28: =(W28/V28*4)+(X28/V28*3)+(Y28/V28*2)+(Z28/V28*1) -> #DIV/0! | AJ28: =(AB28/AA28*4)+(AC28/AA28*3)+(AD28/AA28*2)+(AE28/AA28*1) -> #DIV/0! | AO28: =AF28*$AO$3 -> #DIV/0! | AP28: =AG28*$AP$3 -> #DIV/0! | AQ28: =AH28*$AQ$3 -> #DIV/0! | AR28: =AI28*$AR$3 -> #DIV/0! | AS28: =AJ28*$AS$3 -> #DIV/0! | AT28: =AK28*$AT$3 -> 0 | AU28: =AL28*$AU$3 -> 0 | AV28: =AM28*$AV$3 -> 0 | AW28: =(AO28)+(AP28)+(AT28)+(AU28)+(AV28) -> #DIV/0!
B29: KV 9 | C29: 3 | AF29: =(H29/G29*4)+(I29/G29*3)+(J29/G29*2)+(K29/G29*1) -> #DIV/0! | AG29: =(M29/L29*4)+(N29/L29*3)+(O29/L29*2)+(P29/L29*1) -> #DIV/0! | AH29: =(R29/Q29*4)+(S29/Q29*3)+(T29/Q29*2)+(U29/Q29*1) -> #DIV/0! | AI29: =(W29/V29*4)+(X29/V29*3)+(Y29/V29*2)+(Z29/V29*1) -> #DIV/0! | AJ29: =(AB29/AA29*4)+(AC29/AA29*3)+(AD29/AA29*2)+(AE29/AA29*1) -> #DIV/0! | AO29: =AF29*$AO$3 -> #DIV/0! | AP29: =AG29*$AP$3 -> #DIV/0! | AQ29: =AH29*$AQ$3 -> #DIV/0! | AR29: =AI29*$AR$3 -> #DIV/0! | AS29: =AJ29*$AS$3 -> #DIV/0! | AT29: =AK29*$AT$3 -> 0 | AU29: =AL29*$AU$3 -> 0 | AV29: =AM29*$AV$3 -> 0 | AW29: =(AO29)+(AP29)+(AT29)+(AU29)+(AV29) -> #DIV/0!
A30: 1 | B30: AKUÇAN KG DB SK | C30: 54 | D30: 16000 | E30: =D30/F30 -> 16000 | F30: 1 | G30: 1 | H30: 0 | I30: 0 | J30: 0 | K30: 0 | L30: 179 | M30: 24 | N30: 15 | O30: 13 | P30: 21 | Q30: 481 | R30: 56 | S30: 47 | T30: 56 | U30: 35 | V30: 18 | W30: 1 | X30: 1 | Y30: 1 | Z30: 3 | AA30: 1447 | AB30: 121 | AC30: 118 | AD30: 135 | AE30: 129 | AF30: =(H30/G30*4)+(I30/G30*3)+(J30/G30*2)+(K30/G30*1) -> 0 | AG30: =(M30/L30*4)+(N30/L30*3)+(O30/L30*2)+(P30/L30*1) -> 1.0502793 | AH30: =(R30/Q30*4)+(S30/Q30*3)+(T30/Q30*2)+(U30/Q30*1) -> 1.0644491 | AI30: =(W30/V30*4)+(X30/V30*3)+(Y30/V30*2)+(Z30/V30*1) -> 0.66666667 | AJ30: =(AB30/AA30*4)+(AC30/AA30*3)+(AD30/AA30*2)+(AE30/AA30*1) -> 0.85487215 | AK30: =AVERAGE(AH30:AJ30) -> 0.86199596 | AL30: =E30/MAX($E$30:$E$37) -> 0.125 | AM30: =(AVERAGE($C$30:$C$37)-C30)/AVERAGE($C$30:$C$37) -> 0.042128603 | AO30: =AF30*$AO$3 -> 0 | AP30: =AG30*$AP$3 -> 36.759777 | AQ30: =AH30*$AQ$3 -> 8.5155925 | AR30: =AI30*$AR$3 -> 4 | AS30: =AJ30*$AS$3 -> 1.7097443 | AT30: =AK30*$AT$3 -> 4.3099798 | AU30: =AL30*$AU$3 -> 0.625 | AV30: =AM30*$AV$3 -> 0.42128603 | AW30: =(AO30)+(AP30)+(AT30)+(AU30)+(AV30) -> 42.116042 | AY30: 6 | AZ30: 185.91379
A31: 2 | B31: ASIL OĞUL KG SK | C31: 57 | D31: 130900 | E31: =D31/F31 -> 65450 | F31: 2 | G31: 2 | H31: 0 | I31: 1 | J31: 0 | K31: 1 | L31: 107 | M31: 8 | N31: 8 | O31: 12 | P31: 10 | Q31: 555 | R31: 69 | S31: 60 | T31: 48 | U31: 48 | V31: 30 | W31: 8 | X31: 6 | Y31: 4 | Z31: 5 | AA31: 5789 | AB31: 604 | AC31: 553 | AD31: 556 | AE31: 571 | AF31: =(H31/G31*4)+(I31/G31*3)+(J31/G31*2)+(K31/G31*1) -> 2 | AG31: =(M31/L31*4)+(N31/L31*3)+(O31/L31*2)+(P31/L31*1) -> 0.8411215 | AH31: =(R31/Q31*4)+(S31/Q31*3)+(T31/Q31*2)+(U31/Q31*1) -> 1.0810811 | AI31: =(W31/V31*4)+(X31/V31*3)+(Y31/V31*2)+(Z31/V31*1) -> 2.1 | AJ31: =(AB31/AA31*4)+(AC31/AA31*3)+(AD31/AA31*2)+(AE31/AA31*1) -> 0.99464502 | AK31: =AVERAGE(AH31:AJ31) -> 1.3919087 | AL31: =E31/MAX($E$30:$E$37) -> 0.51132813 | AM31: =(AVERAGE($C$30:$C$37)-C31)/AVERAGE($C$30:$C$37) -> -0.011086475 | AO31: =AF31*$AO$3 -> 90 | AP31: =AG31*$AP$3 -> 29.439252 | AQ31: =AH31*$AQ$3 -> 8.6486486 | AR31: =AI31*$AR$3 -> 12.6 | AS31: =AJ31*$AS$3 -> 1.98929 | AT31: =AK31*$AT$3 -> 6.9595435 | AU31: =AL31*$AU$3 -> 2.5566406 | AV31: =AM31*$AV$3 -> -0.11086475 | AW31: =(AO31)+(AP31)+(AT31)+(AU31)+(AV31) -> 128.84457 | AY31: 5 | AZ31: 168.48156
A32: 3 | B32: DENİZBEYİM KG SK | C32: 57 | D32: 16000 | E32: =D32/F32 -> 16000 | F32: 1 | G32: 1 | H32: 0 | I32: 0 | J32: 0 | K32: 0 | L32: 270 | M32: 59 | N32: 56 | O32: 38 | P32: 36 | Q32: 1416 | R32: 118 | S32: 125 | T32: 132 | U32: 114 | V32: 145 | W32: 9 | X32: 22 | Y32: 18 | Z32: 12 | AA32: 3548 | AB32: 321 | AC32: 326 | AD32: 347 | AE32: 317 | AF32: =(H32/G32*4)+(I32/G32*3)+(J32/G32*2)+(K32/G32*1) -> 0 | AG32: =(M32/L32*4)+(N32/L32*3)+(O32/L32*2)+(P32/L32*1) -> 1.9111111 | AH32: =(R32/Q32*4)+(S32/Q32*3)+(T32/Q32*2)+(U32/Q32*1) -> 0.86511299 | AI32: =(W32/V32*4)+(X32/V32*3)+(Y32/V32*2)+(Z32/V32*1) -> 1.0344828 | AJ32: =(AB32/AA32*4)+(AC32/AA32*3)+(AD32/AA32*2)+(AE32/AA32*1) -> 0.92249154 | AK32: =AVERAGE(AH32:AJ32) -> 0.94069577 | AL32: =E32/MAX($E$30:$E$37) -> 0.125 | AM32: =(AVERAGE($C$30:$C$37)-C32)/AVERAGE($C$30:$C$37) -> -0.011086475 | AO32: =AF32*$AO$3 -> 0 | AP32: =AG32*$AP$3 -> 66.888889 | AQ32: =AH32*$AQ$3 -> 6.920904 | AR32: =AI32*$AR$3 -> 6.2068966 | AS32: =AJ32*$AS$3 -> 1.8449831 | AT32: =AK32*$AT$3 -> 4.7034788 | AU32: =AL32*$AU$3 -> 0.625 | AV32: =AM32*$AV$3 -> -0.11086475 | AW32: =(AO32)+(AP32)+(AT32)+(AU32)+(AV32) -> 72.106503 | AY32: 4 | AZ32: 148.20297
A33: 4 | B33: LUXOR BOY K | C33: 57 | D33: 54600 | E33: =D33/F33 -> 54600 | F33: 1 | G33: 1 | H33: 0 | I33: 0 | J33: 1 | K33: 0 | L33: 301 | M33: 37 | N33: 40 | O33: 61 | P33: 41 | Q33: 14037 | R33: 1795 | S33: 1680 | T33: 1464 | U33: 1422 | V33: 89 | W33: 16 | X33: 9 | Y33: 16 | Z33: 5 | AA33: 14360 | AB33: 1509 | AC33: 1475 | AD33: 1390 | AE33: 1409 | AF33: =(H33/G33*4)+(I33/G33*3)+(J33/G33*2)+(K33/G33*1) -> 2 | AG33: =(M33/L33*4)+(N33/L33*3)+(O33/L33*2)+(P33/L33*1) -> 1.4318937 | AH33: =(R33/Q33*4)+(S33/Q33*3)+(T33/Q33*2)+(U33/Q33*1) -> 1.1804517 | AI33: =(W33/V33*4)+(X33/V33*3)+(Y33/V33*2)+(Z33/V33*1) -> 1.4382022 | AJ33: =(AB33/AA33*4)+(AC33/AA33*3)+(AD33/AA33*2)+(AE33/AA33*1) -> 1.020195 | AK33: =AVERAGE(AH33:AJ33) -> 1.2129496 | AL33: =E33/MAX($E$30:$E$37) -> 0.4265625 | AM33: =(AVERAGE($C$30:$C$37)-C33)/AVERAGE($C$30:$C$37) -> -0.011086475 | AO33: =AF33*$AO$3 -> 90 | AP33: =AG33*$AP$3 -> 50.116279 | AQ33: =AH33*$AQ$3 -> 9.4436133 | AR33: =AI33*$AR$3 -> 8.6292135 | AS33: =AJ33*$AS$3 -> 2.04039 | AT33: =AK33*$AT$3 -> 6.0647482 | AU33: =AL33*$AU$3 -> 2.1328125 | AV33: =AM33*$AV$3 -> -0.11086475 | AW33: =(AO33)+(AP33)+(AT33)+(AU33)+(AV33) -> 148.20297 | AY33: 7 | AZ33: 130.49917
A34: 5 | B34: ÖZTAMER KG K | C34: 57 | D34: 64000 | E34: =D34/F34 -> 64000 | F34: 1 | G34: 1 | H34: 0 | I34: 0 | J34: 1 | K34: 0 | L34: 344 | M34: 90 | N34: 60 | O34: 53 | P34: 45 | Q34: 7006 | R34: 803 | S34: 777 | T34: 835 | U34: 813 | V34: 136 | W34: 27 | X34: 9 | Y34: 14 | Z34: 11 | AA34: 2790 | AB34: 303 | AC34: 291 | AD34: 274 | AE34: 289 | AF34: =(H34/G34*4)+(I34/G34*3)+(J34/G34*2)+(K34/G34*1) -> 2 | AG34: =(M34/L34*4)+(N34/L34*3)+(O34/L34*2)+(P34/L34*1) -> 2.0087209 | AH34: =(R34/Q34*4)+(S34/Q34*3)+(T34/Q34*2)+(U34/Q34*1) -> 1.1455895 | AI34: =(W34/V34*4)+(X34/V34*3)+(Y34/V34*2)+(Z34/V34*1) -> 1.2794118 | AJ34: =(AB34/AA34*4)+(AC34/AA34*3)+(AD34/AA34*2)+(AE34/AA34*1) -> 1.0473118 | AK34: =AVERAGE(AH34:AJ34) -> 1.1574377 | AL34: =E34/MAX($E$30:$E$37) -> 0.5 | AM34: =(AVERAGE($C$30:$C$37)-C34)/AVERAGE($C$30:$C$37) -> -0.011086475 | AO34: =AF34*$AO$3 -> 90 | AP34: =AG34*$AP$3 -> 70.305233 | AQ34: =AH34*$AQ$3 -> 9.164716 | AR34: =AI34*$AR$3 -> 7.6764706 | AS34: =AJ34*$AS$3 -> 2.0946237 | AT34: =AK34*$AT$3 -> 5.7871885 | AU34: =AL34*$AU$3 -> 2.5 | AV34: =AM34*$AV$3 -> -0.11086475 | AW34: =(AO34)+(AP34)+(AT34)+(AU34)+(AV34) -> 168.48156 | AY34: 2 | AZ34: 128.84457
A35: 6 | B35: UTKAN KG K | C35: 57 | D35: 128000 | E35: =D35/F35 -> 128000 | F35: 1 | G35: 1 | H35: 0 | I35: 1 | J35: 0 | K35: 0 | L35: 9013 | M35: 1152 | N35: 1103 | O35: 1146 | P35: 1069 | Q35: 373 | R35: 35 | S35: 37 | T35: 27 | U35: 34 | V35: 7 | W35: 0 | X35: 1 | Y35: 0 | Z35: 0 | AA35: 1 | AB35: 0 | AC35: 0 | AD35: 0 | AE35: 0 | AF35: =(H35/G35*4)+(I35/G35*3)+(J35/G35*2)+(K35/G35*1) -> 3 | AG35: =(M35/L35*4)+(N35/L35*3)+(O35/L35*2)+(P35/L35*1) -> 1.2513037 | AH35: =(R35/Q35*4)+(S35/Q35*3)+(T35/Q35*2)+(U35/Q35*1) -> 0.90884718 | AI35: =(W35/V35*4)+(X35/V35*3)+(Y35/V35*2)+(Z35/V35*1) -> 0.42857143 | AJ35: =(AB35/AA35*4)+(AC35/AA35*3)+(AD35/AA35*2)+(AE35/AA35*1) -> 0 | AK35: =AVERAGE(AH35:AJ35) -> 0.4458062 | AL35: =E35/MAX($E$30:$E$37) -> 1 | AM35: =(AVERAGE($C$30:$C$37)-C35)/AVERAGE($C$30:$C$37) -> -0.011086475 | AO35: =AF35*$AO$3 -> 135 | AP35: =AG35*$AP$3 -> 43.795629 | AQ35: =AH35*$AQ$3 -> 7.2707775 | AR35: =AI35*$AR$3 -> 2.5714286 | AS35: =AJ35*$AS$3 -> 0 | AT35: =AK35*$AT$3 -> 2.229031 | AU35: =AL35*$AU$3 -> 5 | AV35: =AM35*$AV$3 -> -0.11086475 | AW35: =(AO35)+(AP35)+(AT35)+(AU35)+(AV35) -> 185.91379 | AY35: 3 | AZ35: 72.106503
A36: 7 | B36: YİĞİT BOYRAZ KG DB SK | C36: 57 | D36: 20000 | E36: =D36/F36 -> 20000 | F36: 1 | G36: 1 | H36: 0 | I36: 0 | J36: 0 | K36: 1 | L36: 27 | M36: 10 | N36: 4 | O36: 2 | P36: 5 | Q36: 11 | R36: 2 | S36: 2 | T36: 1 | U36: 1 | V36: 5 | W36: 0 | X36: 1 | Y36: 0 | Z36: 2 | AA36: 1479 | AB36: 129 | AC36: 137 | AD36: 126 | AE36: 163 | AF36: =(H36/G36*4)+(I36/G36*3)+(J36/G36*2)+(K36/G36*1) -> 1 | AG36: =(M36/L36*4)+(N36/L36*3)+(O36/L36*2)+(P36/L36*1) -> 2.2592593 | AH36: =(R36/Q36*4)+(S36/Q36*3)+(T36/Q36*2)+(U36/Q36*1) -> 1.5454545 | AI36: =(W36/V36*4)+(X36/V36*3)+(Y36/V36*2)+(Z36/V36*1) -> 1 | AJ36: =(AB36/AA36*4)+(AC36/AA36*3)+(AD36/AA36*2)+(AE36/AA36*1) -> 0.90736984 | AK36: =AVERAGE(AH36:AJ36) -> 1.1509415 | AL36: =E36/MAX($E$30:$E$37) -> 0.15625 | AM36: =(AVERAGE($C$30:$C$37)-C36)/AVERAGE($C$30:$C$37) -> -0.011086475 | AO36: =AF36*$AO$3 -> 45 | AP36: =AG36*$AP$3 -> 79.074074 | AQ36: =AH36*$AQ$3 -> 12.363636 | AR36: =AI36*$AR$3 -> 6 | AS36: =AJ36*$AS$3 -> 1.8147397 | AT36: =AK36*$AT$3 -> 5.7547073 | AU36: =AL36*$AU$3 -> 0.78125 | AV36: =AM36*$AV$3 -> -0.11086475 | AW36: =(AO36)+(AP36)+(AT36)+(AU36)+(AV36) -> 130.49917 | AY36: 1 | AZ36: 42.116042
A37: 8 | B37: İĞDE AĞACI KG K | C37: 55 | D37: 0 | E37: =D37/F37 -> 0 | F37: 1 | G37: 1 | H37: 0 | I37: 0 | J37: 0 | K37: 0 | L37: 171 | M37: 9 | N37: 15 | O37: 19 | P37: 19 | Q37: 1416 | R37: 118 | S37: 125 | T37: 132 | U37: 114 | V37: 1 | W37: 0 | X37: 0 | Y37: 0 | Z37: 0 | AA37: 11 | AB37: 1 | AC37: 0 | AD37: 0 | AE37: 0 | AF37: =(H37/G37*4)+(I37/G37*3)+(J37/G37*2)+(K37/G37*1) -> 0 | AG37: =(M37/L37*4)+(N37/L37*3)+(O37/L37*2)+(P37/L37*1) -> 0.80701754 | AH37: =(R37/Q37*4)+(S37/Q37*3)+(T37/Q37*2)+(U37/Q37*1) -> 0.86511299 | AI37: =(W37/V37*4)+(X37/V37*3)+(Y37/V37*2)+(Z37/V37*1) -> 0 | AJ37: =(AB37/AA37*4)+(AC37/AA37*3)+(AD37/AA37*2)+(AE37/AA37*1) -> 0.36363636 | AK37: =AVERAGE(AH37:AJ37) -> 0.40958312 | AL37: =E37/MAX($E$30:$E$37) -> 0 | AM37: =(AVERAGE($C$30:$C$37)-C37)/AVERAGE($C$30:$C$37) -> 0.024390244 | AO37: =AF37*$AO$3 -> 0 | AP37: =AG37*$AP$3 -> 28.245614 | AQ37: =AH37*$AQ$3 -> 6.920904 | AR37: =AI37*$AR$3 -> 0 | AS37: =AJ37*$AS$3 -> 0.72727273 | AT37: =AK37*$AT$3 -> 2.0479156 | AU37: =AL37*$AU$3 -> 0 | AV37: =AM37*$AV$3 -> 0.24390244 | AW37: =(AO37)+(AP37)+(AT37)+(AU37)+(AV37) -> 30.537432 | AY37: 8 | AZ37: 30.537432
AF38: =(H38/G38*4)+(I38/G38*3)+(J38/G38*2)+(K38/G38*1) -> #DIV/0! | AG38: =(M38/L38*4)+(N38/L38*3)+(O38/L38*2)+(P38/L38*1) -> #DIV/0! | AH38: =(R38/Q38*4)+(S38/Q38*3)+(T38/Q38*2)+(U38/Q38*1) -> #DIV/0! | AI38: =(W38/V38*4)+(X38/V38*3)+(Y38/V38*2)+(Z38/V38*1) -> #DIV/0! | AJ38: =(AB38/AA38*4)+(AC38/AA38*3)+(AD38/AA38*2)+(AE38/AA38*1) -> #DIV/0! | AO38: =AF38*$AO$3 -> #DIV/0! | AP38: =AG38*$AP$3 -> #DIV/0! | AQ38: =AH38*$AQ$3 -> #DIV/0! | AR38: =AI38*$AR$3 -> #DIV/0! | AS38: =AJ38*$AS$3 -> #DIV/0! | AT38: =AK38*$AT$3 -> 0 | AU38: =AL38*$AU$3 -> 0 | AV38: =AM38*$AV$3 -> 0 | AW38: =(AO38)+(AP38)+(AT38)+(AU38)+(AV38) -> #DIV/0!
B39: HAND 15 | C39: 4 | AF39: =(H39/G39*4)+(I39/G39*3)+(J39/G39*2)+(K39/G39*1) -> #DIV/0! | AG39: =(M39/L39*4)+(N39/L39*3)+(O39/L39*2)+(P39/L39*1) -> #DIV/0! | AH39: =(R39/Q39*4)+(S39/Q39*3)+(T39/Q39*2)+(U39/Q39*1) -> #DIV/0! | AI39: =(W39/V39*4)+(X39/V39*3)+(Y39/V39*2)+(Z39/V39*1) -> #DIV/0! | AJ39: =(AB39/AA39*4)+(AC39/AA39*3)+(AD39/AA39*2)+(AE39/AA39*1) -> #DIV/0! | AO39: =AF39*$AO$3 -> #DIV/0! | AP39: =AG39*$AP$3 -> #DIV/0! | AQ39: =AH39*$AQ$3 -> #DIV/0! | AR39: =AI39*$AR$3 -> #DIV/0! | AS39: =AJ39*$AS$3 -> #DIV/0! | AT39: =AK39*$AT$3 -> 0 | AU39: =AL39*$AU$3 -> 0 | AV39: =AM39*$AV$3 -> 0 | AW39: =(AO39)+(AP39)+(AT39)+(AU39)+(AV39) -> #DIV/0!
A40: 1 | B40: HATIR SAYAN KG SK | C40: 59 | D40: 317000 | E40: =D40/F40 -> 31700 | F40: 10 | G40: 10 | H40: 1 | I40: 1 | J40: 1 | K40: 0 | L40: 141 | M40: 7 | N40: 11 | O40: 15 | P40: 9 | Q40: 704 | R40: 65 | S40: 57 | T40: 71 | U40: 72 | V40: 61 | W40: 6 | X40: 7 | Y40: 6 | Z40: 2 | AA40: 11 | AB40: 1 | AC40: 0 | AD40: 0 | AE40: 0 | AF40: =(H40/G40*4)+(I40/G40*3)+(J40/G40*2)+(K40/G40*1) -> 0.9 | AG40: =(M40/L40*4)+(N40/L40*3)+(O40/L40*2)+(P40/L40*1) -> 0.70921986 | AH40: =(R40/Q40*4)+(S40/Q40*3)+(T40/Q40*2)+(U40/Q40*1) -> 0.91619318 | AI40: =(W40/V40*4)+(X40/V40*3)+(Y40/V40*2)+(Z40/V40*1) -> 0.96721311 | AJ40: =(AB40/AA40*4)+(AC40/AA40*3)+(AD40/AA40*2)+(AE40/AA40*1) -> 0.36363636 | AK40: =AVERAGE(AH40:AJ40) -> 0.74901422 | AL40: =E40/MAX($E$40:$E$47) -> 0.4872051 | AM40: =(AVERAGE($C$40:$C$47)-C40)/AVERAGE($C$40:$C$47) -> -0.041942605 | AO40: =AF40*$AO$3 -> 40.5 | AP40: =AG40*$AP$3 -> 24.822695 | AQ40: =AH40*$AQ$3 -> 7.3295455 | AR40: =AI40*$AR$3 -> 5.8032787 | AS40: =AJ40*$AS$3 -> 0.72727273 | AT40: =AK40*$AT$3 -> 3.7450711 | AU40: =AL40*$AU$3 -> 2.4360255 | AV40: =AM40*$AV$3 -> -0.41942605 | AW40: =(AO40)+(AP40)+(AT40)+(AU40)+(AV40) -> 71.084366 | AY40: 3 | AZ40: 141.66955
...

Sheet result
I2: KÜÇÜK | J2: ORTA | K2: BÜYÜK
C3: HAND 16 | D3: NO | E3: SCORE | G3: 1 | I3: SMALL | J3: MEDIUM | K3: BIG
B4: 1 | C4: HEKİMOĞLU KG DB SK | D4: =ANALİZ!AY6 -> 4 | E4: =ANALİZ!AZ6 -> 169.31356 | G4: =IF(ROWS($G$4:G4)>5,"X",IF(ROW()=6,"KÜÇÜK",IF($E$4-E4<=20,"KÜÇÜK",IF($E$4-E4<=50,"ORTA",IF($E$4-E4<=57,"BÜYÜK","X"))))) -> KÜÇÜK | I4: =IF($G4="Küçük",$D4,"") -> 4 | J4: =IF($G4="Orta",$D4,"") | K4: =IF($G4="Büyük",$D4,"")
B5: 2 | C5: DELİ YILDIRIM KG DB SK | D5: =ANALİZ!AY7 -> 3 | E5: =ANALİZ!AZ7 -> 159.52978 | F5: =$E$4-E5 -> 9.7837745 | G5: =IF(ROWS($G$4:G5)>5,"X",IF(ROW()=6,"KÜÇÜK",IF($E$4-E5<=20,"KÜÇÜK",IF($E$4-E5<=50,"ORTA",IF($E$4-E5<=57,"BÜYÜK","X"))))) -> KÜÇÜK | I5: =IF($G5="Küçük",$D5,"") -> 3 | J5: =IF($G5="Orta",$D5,"") | K5: =IF($G5="Büyük",$D5,"")
B6: 3 | C6: CANYURT KG DB SK | D6: =ANALİZ!AY8 -> 8 | E6: =ANALİZ!AZ8 -> 119.57459 | F6: =$E$4-E6 -> 49.738961 | G6: =IF(ROWS($G$4:G6)>5,"X",IF(ROW()=6,"KÜÇÜK",IF($E$4-E6<=20,"KÜÇÜK",IF($E$4-E6<=50,"ORTA",IF($E$4-E6<=57,"BÜYÜK","X"))))) -> KÜÇÜK | I6: =IF($G6="Küçük",$D6,"") -> 8 | J6: =IF($G6="Orta",$D6,"") | K6: =IF($G6="Büyük",$D6,"")
B7: 4 | C7: HIZLI AYAK KG SK | D7: =ANALİZ!AY9 -> 10 | E7: =ANALİZ!AZ9 -> 113.20019 | F7: =$E$4-E7 -> 56.113366 | G7: =IF(ROWS($G$4:G7)>5,"X",IF(ROW()=6,"KÜÇÜK",IF($E$4-E7<=20,"KÜÇÜK",IF($E$4-E7<=50,"ORTA",IF($E$4-E7<=57,"BÜYÜK","X"))))) -> BÜYÜK | I7: =IF($G7="Küçük",$D7,"") | J7: =IF($G7="Orta",$D7,"") | K7: =IF($G7="Büyük",$D7,"") -> 10
B8: 5 | C8: SADEKAR KG DB SK | D8: =ANALİZ!AY10 -> 5 | E8: =ANALİZ!AZ10 -> 82.86819 | F8: =$E$4-E8 -> 86.445366 | G8: =IF(ROWS($G$4:G8)>5,"X",IF(ROW()=6,"KÜÇÜK",IF($E$4-E8<=20,"KÜÇÜK",IF($E$4-E8<=50,"ORTA",IF($E$4-E8<=57,"BÜYÜK","X"))))) -> X | I8: =IF($G8="Küçük",$D8,"") | J8: =IF($G8="Orta",$D8,"") | K8: =IF($G8="Büyük",$D8,"")
B9: 6 | C9: ALEVKIRAN KG DB SK GKR | D9: =ANALİZ!AY11 -> 7 | E9: =ANALİZ!AZ11 -> 81.139711 | F9: =$E$4-E9 -> 88.173844 | G9: =IF(ROWS($G$4:G9)>5,"X",IF(ROW()=6,"KÜÇÜK",IF($E$4-E9<=20,"KÜÇÜK",IF($E$4-E9<=50,"ORTA",IF($E$4-E9<=57,"BÜYÜK","X"))))) -> X
B10: 7 | C10: TURBODİZEL KG | D10: =ANALİZ!AY12 -> 9 | E10: =ANALİZ!AZ12 -> 75.04045 | F10: =$E$4-E10 -> 94.273105 | G10: =IF(ROWS($G$4:G10)>5,"X",IF(ROW()=6,"KÜÇÜK",IF($E$4-E10<=20,"KÜÇÜK",IF($E$4-E10<=50,"ORTA",IF($E$4-E10<=57,"BÜYÜK","X"))))) -> X
B11: 8 | C11: ÇAĞLAYANŞELALE KG K DB | D11: =ANALİZ!AY13 -> 2 | E11: =ANALİZ!AZ13 -> 74.710487 | F11: =$E$4-E11 -> 94.603068 | G11: =IF(ROWS($G$4:G11)>5,"X",IF(ROW()=6,"KÜÇÜK",IF($E$4-E11<=20,"KÜÇÜK",IF($E$4-E11<=50,"ORTA",IF($E$4-E11<=57,"BÜYÜK","X"))))) -> X
B12: 9 | C12: HOSLİ KG DB SK GKR | D12: =ANALİZ!AY14 -> 1 | E12: =ANALİZ!AZ14 -> 73.069596 | F12: =$E$4-E12 -> 96.243959 | G12: =IF(ROWS($G$4:G12)>5,"X",IF(ROW()=6,"KÜÇÜK",IF($E$4-E12<=20,"KÜÇÜK",IF($E$4-E12<=50,"ORTA",IF($E$4-E12<=57,"BÜYÜK","X"))))) -> X
B13: 10 | C13: KUNYA KG K DB | D13: =ANALİZ!AY15 -> 6 | E13: =ANALİZ!AZ15 -> 57.556058 | F13: =$E$4-E13 -> 111.7575 | G13: =IF(ROWS($G$4:G13)>5,"X",IF(ROW()=6,"KÜÇÜK",IF($E$4-E13<=20,"KÜÇÜK",IF($E$4-E13<=50,"ORTA",IF($E$4-E13<=57,"BÜYÜK","X"))))) -> X
I14: KÜÇÜK | J14: ORTA | K14: BÜYÜK
C15: HAND 17 | G15: 2 | I15: SMALL | J15: MEDIUM | K15: BIG
B16: 1 | C16: OKLAHOMA DB SK | D16: =ANALİZ!AY18 -> 3 | E16: =ANALİZ!AZ18 -> 171.67878 | G16: =IF(ROWS($G$16:G16)>5,"X",IF(ROW()=6,"KÜÇÜK",IF($E$16-E16<=20,"KÜÇÜK",IF($E$16-E16<=50,"ORTA",IF($E$16-E16<=57,"BÜYÜK","X"))))) -> KÜÇÜK | I16: =IF($G16="Küçük",$D16,"") -> 3 | J16: =IF($G16="Orta",$D16,"") | K16: =IF($G16="Büyük",$D16,"")
B17: 2 | C17: ÇAKIR YILDIZI KG SK GKR | D17: =ANALİZ!AY19 -> 8 | E17: =ANALİZ!AZ19 -> 166.35458 | F17: =$E$16-E17 -> 5.3242071 | G17: =IF(ROWS($G$16:G17)>5,"X",IF(ROW()=6,"KÜÇÜK",IF($E$16-E17<=20,"KÜÇÜK",IF($E$16-E17<=50,"ORTA",IF($E$16-E17<=57,"BÜYÜK","X"))))) -> KÜÇÜK | I17: =IF($G17="Küçük",$D17,"") -> 8 | J17: =IF($G17="Orta",$D17,"") | K17: =IF($G17="Büyük",$D17,"")
B18: 3 | C18: ASLAN LUİGİ K | D18: =ANALİZ!AY20 -> 2 | E18: =ANALİZ!AZ20 -> 137.73123 | F18: =$E$16-E18 -> 33.947553 | G18: =IF(ROWS($G$16:G18)>5,"X",IF(ROW()=6,"KÜÇÜK",IF($E$16-E18<=20,"KÜÇÜK",IF($E$16-E18<=50,"ORTA",IF($E$16-E18<=57,"BÜYÜK","X"))))) -> ORTA | I18: =IF($G18="Küçük",$D18,"") | J18: =IF($G18="Orta",$D18,"") -> 2 | K18: =IF($G18="Büyük",$D18,"")
B19: 4 | C19: KUMTEPER DB SKG SK SGKR | D19: =ANALİZ!AY21 -> 5 | E19: =ANALİZ!AZ21 -> 133.94873 | F19: =$E$16-E19 -> 37.730058 | G19: =IF(ROWS($G$16:G19)>5,"X",IF(ROW()=6,"KÜÇÜK",IF($E$16-E19<=20,"KÜÇÜK",IF($E$16-E19<=50,"ORTA",IF($E$16-E19<=57,"BÜYÜK","X"))))) -> ORTA | I19: =IF($G19="Küçük",$D19,"") | J19: =IF($G19="Orta",$D19,"") -> 5 | K19: =IF($G19="Büyük",$D19,"")
B20: 5 | C20: SWEPS KG DB SK | D20: =ANALİZ!AY22 -> 9 | E20: =ANALİZ!AZ22 -> 131.4517 | F20: =$E$16-E20 -> 40.227083 | G20: =IF(ROWS($G$16:G20)>5,"X",IF(ROW()=6,"KÜÇÜK",IF($E$16-E20<=20,"KÜÇÜK",IF($E$16-E20<=50,"ORTA",IF($E$16-E20<=57,"BÜYÜK","X"))))) -> ORTA | I20: =IF($G20="Küçük",$D20,"") | J20: =IF($G20="Orta",$D20,"") -> 9 | K20: =IF($G20="Büyük",$D20,"")
B21: 6 | C21: FOUDROYANT K DB | D21: =ANALİZ!AY23 -> 4 | E21: =ANALİZ!AZ23 -> 126.18027 | F21: =$E$16-E21 -> 45.498514 | G21: =IF(ROWS($G$16:G21)>5,"X",IF(ROW()=6,"KÜÇÜK",IF($E$16-E21<=20,"KÜÇÜK",IF($E$16-E21<=50,"ORTA",IF($E$16-E21<=57,"BÜYÜK","X"))))) -> X
B22: 7 | C22: MR BIG SHOT DB BB | D22: =ANALİZ!AY24 -> 1 | E22: =ANALİZ!AZ24 -> 126.17425 | F22: =$E$16-E22 -> 45.504534 | G22: =IF(ROWS($G$16:G22)>5,"X",IF(ROW()=6,"KÜÇÜK",IF($E$16-E22<=20,"KÜÇÜK",IF($E$16-E22<=50,"ORTA",IF($E$16-E22<=57,"BÜYÜK","X"))))) -> X
B23: 8 | C23: SİLİSTRE KG K | D23: =ANALİZ!AY25 -> 6 | E23: =ANALİZ!AZ25 -> 117.68512 | F23: =$E$16-E23 -> 53.993663 | G23: =IF(ROWS($G$16:G23)>5,"X",IF(ROW()=6,"KÜÇÜK",IF($E$16-E23<=20,"KÜÇÜK",IF($E$16-E23<=50,"ORTA",IF($E$16-E23<=57,"BÜYÜK","X"))))) -> X
B24: 9 | C24: CATCH THE STARS SK | D24: =ANALİZ!AY26 -> 10 | E24: =ANALİZ!AZ26 -> 106.90864 | F24: =$E$16-E24 -> 64.770145 | G24: =IF(ROWS($G$16:G24)>5,"X",IF(ROW()=6,"KÜÇÜK",IF($E$16-E24<=20,"KÜÇÜK",IF($E$16-E24<=50,"ORTA",IF($E$16-E24<=57,"BÜYÜK","X"))))) -> X
B25: 10 | C25: KING OF THE WIN KG DB SK | D25: =ANALİZ!AY27 -> 7 | E25: =ANALİZ!AZ27 -> 105.08775 | F25: =$E$16-E25 -> 66.591038 | G25: =IF(ROWS($G$16:G25)>5,"X",IF(ROW()=6,"KÜÇÜK",IF($E$16-E25<=20,"KÜÇÜK",IF($E$16-E25<=50,"ORTA",IF($E$16-E25<=57,"BÜYÜK","X"))))) -> X
I26: KÜÇÜK | J26: ORTA | K26: BÜYÜK
C27: KV 9 | D27: SIRA | E27: KÜÇÜK | G27: 1 | I27: SMALL | J27: MEDIUM | K27: BIG
B28: 1 | C28: AKUÇAN KG DB SK | D28: =ANALİZ!AY30 -> 6 | E28: =ANALİZ!AZ30 -> 185.91379 | G28: =IF(ROWS($G$28:G28)>5,"X",IF(ROW()=6,"KÜÇÜK",IF($E$28-E28<=20,"KÜÇÜK",IF($E$28-E28<=50,"ORTA",IF($E$28-E28<=57,"BÜYÜK","X"))))) -> KÜÇÜK | I28: =IF($G28="Küçük",$D28,"") -> 6 | J28: =IF($G28="Orta",$D28,"") | K28: =IF($G28="Büyük",$D28,"")
B29: 2 | C29: ASIL OĞUL KG SK | D29: =ANALİZ!AY31 -> 5 | E29: =ANALİZ!AZ31 -> 168.48156 | F29: =$E$28-E29 -> 17.432239 | G29: =IF(ROWS($G$28:G29)>5,"X",IF(ROW()=6,"KÜÇÜK",IF($E$28-E29<=20,"KÜÇÜK",IF($E$28-E29<=50,"ORTA",IF($E$28-E29<=57,"BÜYÜK","X"))))) -> KÜÇÜK | I29: =IF($G29="Küçük",$D29,"") -> 5 | J29: =IF($G29="Orta",$D29,"") | K29: =IF($G29="Büyük",$D29,"")
B30: 3 | C30: DENİZBEYİM KG SK | D30: =ANALİZ!AY32 -> 4 | E30: =ANALİZ!AZ32 -> 148.20297 | F30: =$E$28-E30 -> 37.71082 | G30: =IF(ROWS($G$28:G30)>5,"X",IF(ROW()=6,"KÜÇÜK",IF($E$28-E30<=20,"KÜÇÜK",IF($E$28-E30<=50,"ORTA",IF($E$28-E30<=57,"BÜYÜK","X"))))) -> ORTA | I30: =IF($G30="Küçük",$D30,"") | J30: =IF($G30="Orta",$D30,"") -> 4 | K30: =IF($G30="Büyük",$D30,"")
B31: 4 | C31: LUXOR BOY K | D31: =ANALİZ!AY33 -> 7 | E31: =ANALİZ!AZ33 -> 130.49917 | F31: =$E$28-E31 -> 55.414628 | G31: =IF(ROWS($G$28:G31)>5,"X",IF(ROW()=6,"KÜÇÜK",IF($E$28-E31<=20,"KÜÇÜK",IF($E$28-E31<=50,"ORTA",IF($E$28-E31<=57,"BÜYÜK","X"))))) -> BÜYÜK | I31: =IF($G31="Küçük",$D31,"") | J31: =IF($G31="Orta",$D31,"") | K31: =IF($G31="Büyük",$D31,"") -> 7
B32: 5 | C32: ÖZTAMER KG K | D32: =ANALİZ!AY34 -> 2 | E32: =ANALİZ!AZ34 -> 128.84457 | F32: =$E$28-E32 -> 57.069223 | G32: =IF(ROWS($G$28:G32)>5,"X",IF(ROW()=6,"KÜÇÜK",IF($E$28-E32<=20,"KÜÇÜK",IF($E$28-E32<=50,"ORTA",IF($E$28-E32<=57,"BÜYÜK","X"))))) -> X | I32: =IF($G32="Küçük",$D32,"") | J32: =IF($G32="Orta",$D32,"") | K32: =IF($G32="Büyük",$D32,"")
B33: 6 | C33: UTKAN KG K | D33: =ANALİZ!AY35 -> 3 | E33: =ANALİZ!AZ35 -> 72.106503 | F33: =$E$28-E33 -> 113.80729 | G33: =IF(ROWS($G$28:G33)>5,"X",IF(ROW()=6,"KÜÇÜK",IF($E$28-E33<=20,"KÜÇÜK",IF($E$28-E33<=50,"ORTA",IF($E$28-E33<=57,"BÜYÜK","X"))))) -> X
B34: 7 | C34: YİĞİT BOYRAZ KG DB SK | D34: =ANALİZ!AY36 -> 1 | E34: =ANALİZ!AZ36 -> 42.116042 | F34: =$E$28-E34 -> 143.79775 | G34: =IF(ROWS($G$28:G34)>5,"X",IF(ROW()=6,"KÜÇÜK",IF($E$28-E34<=20,"KÜÇÜK",IF($E$28-E34<=50,"ORTA",IF($E$28-E34<=57,"BÜYÜK","X"))))) -> X
B35: 8 | C35: İĞDE AĞACI KG K | D35: =ANALİZ!AY37 -> 8 | E35: =ANALİZ!AZ37 -> 30.537432 | F35: =$E$28-E35 -> 155.37636 | G35: =IF(ROWS($G$28:G35)>5,"X",IF(ROW()=6,"KÜÇÜK",IF($E$28-E35<=20,"KÜÇÜK",IF($E$28-E35<=50,"ORTA",IF($E$28-E35<=57,"BÜYÜK","X"))))) -> X
I36: KÜÇÜK | J36: ORTA | K36: BÜYÜK
C37: HAND 15 | D37: SIRA | E37: KÜÇÜK | G37: 1 | I37: SMALL | J37: MEDIUM | K37: BIG
B38: 1 | C38: HATIR SAYAN KG SK | D38: =ANALİZ!AY40 -> 3 | E38: =ANALİZ!AZ40 -> 141.66955 | G38: =IF(ROWS($G$38:G38)>5,"X",IF(ROW()=6,"KÜÇÜK",IF($E$38-E38<=20,"KÜÇÜK",IF($E$38-E38<=50,"ORTA",IF($E$38-E38<=57,"BÜYÜK","X"))))) -> KÜÇÜK | I38: =IF($G38="Küçük",$D38,"") -> 3 | J38: =IF($G38="Orta",$D38,"") | K38: =IF($G38="Büyük",$D38,"")
B39: 2 | C39: TILISIM SKG SK | D39: =ANALİZ!AY41 -> 4 | E39: =ANALİZ!AZ41 -> 129.82862 | F39: =$E$38-E39 -> 11.840929 | G39: =IF(ROWS($G$38:G39)>5,"X",IF(ROW()=6,"KÜÇÜK",IF($E$38-E39<=20,"KÜÇÜK",IF($E$38-E39<=50,"ORTA",IF($E$38-E39<=57,"BÜYÜK","X"))))) -> KÜÇÜK | I39: =IF($G39="Küçük",$D39,"") -> 4 | J39: =IF($G39="Orta",$D39,"") | K39: =IF($G39="Büyük",$D39,"")
B40: 3 | C40: ASİ TAHA DB SK | D40: =ANALİZ!AY42 -> 6 | E40: =ANALİZ!AZ42 -> 124.07546 | F40: =$E$38-E40 -> 17.594088 | G40: =IF(ROWS($G$38:G40)>5,"X",IF(ROW()=6,"KÜÇÜK",IF($E$38-E40<=20,"KÜÇÜK",IF($E$38-E40<=50,"ORTA",IF($E$38-E40<=57,"BÜYÜK","X"))))) -> KÜÇÜK | I40: =IF($G40="Küçük",$D40,"") -> 6 | J40: =IF($G40="Orta",$D40,"") | K40: =IF($G40="Büyük",$D40,"")
B41: 4 | C41: PİYANİST SKG SK | D41: =ANALİZ!AY43 -> 2 | E41: =ANALİZ!AZ43 -> 117.94833 | F41: =$E$38-E41 -> 23.721219 | G41: =IF(ROWS($G$38:G41)>5,"X",IF(ROW()=6,"KÜÇÜK",IF($E$38-E41<=20,"KÜÇÜK",IF($E$38-E41<=50,"ORTA",IF($E$38-E41<=57,"BÜYÜK","X"))))) -> ORTA | I41: =IF($G41="Küçük",$D41,"") | J41: =IF($G41="Orta",$D41,"") -> 2 | K41: =IF($G41="Büyük",$D41,"")
...
